Workbook

Sheet Ajuste_por_estrato
A1: Estrato | B1: b0 (logit en 2021) | C1: b1 (cambio del logit por año) | D1: EE de b1 | E1: p de b1 | F1: Sobredispersión (escala) | G1: Olas usadas | H1: Hogares en el ajuste
A2: E1 | B2: -2.2341598 | C2: 0.11815177 | D2: 0.054737876 | E2: 0.030888889 | F2: 3.5686176 | G2: 7 | H2: 2164
A3: E2 | B3: -0.98540996 | C3: 0.037811974 | D3: 0.04349277 | E3: 0.38463644 | F3: 2.4822401 | G3: 7 | H3: 1239
A4: E3 | B4: -0.28125053 | C4: 0.073435473 | D4: 0.027044279 | E4: 0.006619992 | F4: 1 | G4: 7 | H4: 966
A5: E4 | B5: 1.0499379 | C5: 0.090708101 | D5: 0.10815117 | E5: 0.4016288 | F5: 6.7576604 | G5: 7 | H5: 554
A6: E5 | B6: 1.8052669 | C6: 0.072190919 | D6: 0.11448457 | E6: 0.52831955 | F6: 2.2816056 | G6: 7 | H6: 268
A7: E6 | B7: 3.8295391 | C7: 0.18819095 | D7: 0.22830176 | E7: 0.40976461 | F7: 1.0270643 | G7: 7 | H7: 212
A9: Modelo por estrato: logit(p) = b0 + b1·(año − 2021). GLM binomial con las tasas ponderadas de la ECV (P1077S11) y var_weights = n hogares.
A10: Olas: 2018, 2019, 2021, 2022, 2023, 2024, 2025. 2020 se excluye (encuesta en parte telefónica; año excluido de la calibración en la propuesta).
A11: Sobredispersión = estadístico de Pearson / gl (mínimo 1): cuánto varían las olas más de lo que explica el muestreo. Infla la varianza de cada año.
A12: Valores calculados en Python (serie_suavizada.py).

Sheet Serie_estrato
A1: Estrato | B1: Año | C1: Tipo de dato | D1: n ECV | E1: p observada (ECV) | F1: p suavizada (media) | G1: DE | H1: IC90 inf | I1: IC90 sup | J1: Beta alfa | K1: Beta beta | L1: Control: media Beta
A2: E1 | B2: 2015 | C2: extrapolado | F2: 0.050065049 | G2: 0.019118698 | H2: 0.026484191 | I2: 0.092643665 | J2: =F2*(F2*(1-F2)/G2^2-1) -> 6.4639166 | K2: =(1-F2)*(F2*(1-F2)/G2^2-1) -> 122.64645 | L2: =J2/(J2+K2) -> 0.050065049
A3: E1 | B3: 2016 | C3: extrapolado | F3: 0.055992381 | G3: 0.018545547 | H3: 0.032230364 | I3: 0.095543539 | J3: =F3*(F3*(1-F3)/G3^2-1) -> 8.5490713 | K3: =(1-F3)*(F3*(1-F3)/G3^2-1) -> 144.13369 | L3: =J3/(J3+K3) -> 0.055992381
A4: E1 | B4: 2017 | C4: extrapolado | F4: 0.062575239 | G4: 0.017655723 | H4: 0.039094693 | I4: 0.098709667 | J4: =F4*(F4*(1-F4)/G4^2-1) -> 11.712683 | K4: =(1-F4)*(F4*(1-F4)/G4^2-1) -> 175.46491 | L4: =J4/(J4+K4) -> 0.062575239
A5: E1 | B5: 2018 | C5: observado y ajustado | D5: 385 | E5: 0.099297614 | F5: 0.069874739 | G5: 0.016451432 | H5: 0.047199941 | I5: 0.10227324 | J5: =F5*(F5*(1-F5)/G5^2-1) -> 16.709447 | K5: =(1-F5)*(F5*(1-F5)/G5^2-1) -> 222.42486 | L5: =J5/(J5+K5) -> 0.069874739
A6: E1 | B6: 2019 | C6: observado y ajustado | D6: 436 | E6: 0.075856224 | F6: 0.077954927 | G6: 0.014999685 | H6: 0.056585854 | I6: 0.10648297 | J6: =F6*(F6*(1-F6)/G6^2-1) -> 24.826382 | K6: =(1-F6)*(F6*(1-F6)/G6^2-1) -> 293.6446 | L6: =J6/(J6+K6) -> 0.077954927
A7: E1 | B7: 2020 | C7: observado, no usado en el ajuste | D7: 254 | E7: 0.061057293 | F7: 0.086882214 | G7: 0.013513549 | H7: 0.067074733 | I7: 0.11183774 | J7: =F7*(F7*(1-F7)/G7^2-1) -> 37.657273 | K7: =(1-F7)*(F7*(1-F7)/G7^2-1) -> 395.77175 | L7: =J7/(J7+K7) -> 0.086882214
A8: E1 | B8: 2021 | C8: observado y ajustado | D8: 244 | E8: 0.053774853 | F8: 0.096724596 | G8: 0.012501433 | H8: 0.078021373 | I8: 0.11933104 | J8: =F8*(F8*(1-F8)/G8^2-1) -> 53.975528 | K8: =(1-F8)*(F8*(1-F8)/G8^2-1) -> 504.05759 | L8: =J8/(J8+K8) -> 0.096724596
A9: E1 | B9: 2022 | C9: observado y ajustado | D9: 277 | E9: 0.07272544 | F9: 0.10755064 | G9: 0.012850918 | H9: 0.088164783 | I9: 0.13058862 | J9: =F9*(F9*(1-F9)/G9^2-1) -> 62.401265 | K9: =(1-F9)*(F9*(1-F9)/G9^2-1) -> 517.80232 | L9: =J9/(J9+K9) -> 0.10755064
A10: E1 | B10: 2023 | C10: observado y ajustado | D10: 265 | E10: 0.11773933 | F10: 0.11942819 | G10: 0.015373419 | H10: 0.096361002 | I10: 0.14711826 | J10: =F10*(F10*(1-F10)/G10^2-1) -> 53.022526 | K10: =(1-F10)*(F10*(1-F10)/G10^2-1) -> 390.94742 | L10: =J10/(J10+K10) -> 0.11942819
A11: E1 | B11: 2024 | C11: observado y ajustado | D11: 250 | E11: 0.12422018 | F11: 0.13242282 | G11: 0.020164599 | H11: 0.10262156 | I11: 0.16924615 | J11: =F11*(F11*(1-F11)/G11^2-1) -> 37.283341 | K11: =(1-F11)*(F11*(1-F11)/G11^2-1) -> 244.26436 | L11: =J11/(J11+K11) -> 0.13242282
A12: E1 | B12: 2025 | C12: observado y ajustado | D12: 307 | E12: 0.18637367 | F12: 0.14659598 | G12: 0.026900637 | H12: 0.10762185 | I12: 0.19657511 | J12: =F12*(F12*(1-F12)/G12^2-1) -> 25.197317 | K12: =(1-F12)*(F12*(1-F12)/G12^2-1) -> 146.68541 | L12: =J12/(J12+K12) -> 0.14659598
A13: E1 | B13: 2026 | C13: extrapolado | F13: 0.16200283 | G13: 0.035311804 | H13: 0.11191979 | I13: 0.22872541 | J13: =F13*(F13*(1-F13)/G13^2-1) -> 17.47594 | K13: =(1-F13)*(F13*(1-F13)/G13^2-1) -> 90.39835 | L13: =J13/(J13+K13) -> 0.16200283
A14: E1 | B14: 2027 | C14: extrapolado | F14: 0.17868985 | G14: 0.045251158 | H14: 0.11583673 | I14: 0.26540969 | J14: =F14*(F14*(1-F14)/G14^2-1) -> 12.628315 | K14: =(1-F14)*(F14*(1-F14)/G14^2-1) -> 58.043381 | L14: =J14/(J14+K14) -> 0.17868985
A15: E2 | B15: 2015 | C15: extrapolado | F15: 0.22929756 | G15: 0.054021483 | H15: 0.15249812 | I15: 0.32972639 | J15: =F15*(F15*(1-F15)/G15^2-1) -> 13.655917 | K15: =(1-F15)*(F15*(1-F15)/G15^2-1) -> 45.899522 | L15: =J15/(J15+K15) -> 0.22929756
A16: E2 | B16: 2016 | C16: extrapolado | F16: 0.23604799 | G16: 0.047783967 | H16: 0.16653799 | I16: 0.32331583 | J16: =F16*(F16*(1-F16)/G16^2-1) -> 18.406372 | K16: =(1-F16)*(F16*(1-F16)/G16^2-1) -> 59.570874 | L16: =J16/(J16+K16) -> 0.23604799
A17: E2 | B17: 2017 | C17: extrapolado | F17: 0.24293451 | G17: 0.041439726 | H17: 0.1813386 | I17: 0.3173426 | J17: =F17*(F17*(1-F17)/G17^2-1) -> 25.775318 | K17: =(1-F17)*(F17*(1-F17)/G17^2-1) -> 80.324544 | L17: =J17/(J17+K17) -> 0.24293451
A18: E2 | B18: 2018 | C18: observado y ajustado | D18: 198 | E18: 0.30001284 | F18: 0.2499562 | G18: 0.035125803 | H18: 0.19669941 | I18: 0.31203137 | J18: =F18*(F18*(1-F18)/G18^2-1) -> 37.730654 | K18: =(1-F18)*(F18*(1-F18)/G18^2-1) -> 113.21841 | L18: =J18/(J18+K18) -> 0.2499562
A19: E2 | B19: 2019 | C19: observado y ajustado | D19: 155 | E19: 0.25712342 | F19: 0.25711192 | G19: 0.029107238 | H19: 0.21220003 | I19: 0.30781528 | J19: =F19*(F19*(1-F19)/G19^2-1) -> 57.707887 | K19: =(1-F19)*(F19*(1-F19)/G19^2-1) -> 166.73868 | L19: =J19/(J19+K19) -> 0.25711192
A20: E2 | B20: 2020 | C20: observado, no usado en el ajuste | D20: 180 | E20: 0.27957752 | F20: 0.26440028 | G20: 0.023919332 | H20: 0.22696488 | I20: 0.30556954 | J20: =F20*(F20*(1-F20)/G20^2-1) -> 89.616471 | K20: =(1-F20)*(F20*(1-F20)/G20^2-1) -> 249.32595 | L20: =J20/(J20+K20) -> 0.26440028
A21: E2 | B21: 2021 | C21: observado y ajustado | D21: 224 | E21: 0.23690347 | F21: 0.27181965 | G21: 0.020579733 | H21: 0.23931379 | I21: 0.30695907 | J21: =F21*(F21*(1-F21)/G21^2-1) -> 126.76254 | K21: =(1-F21)*(F21*(1-F21)/G21^2-1) -> 339.58542 | L21: =J21/(J21+K21) -> 0.27181965
A22: E2 | B22: 2022 | C22: observado y ajustado | D22: 184 | E22: 0.20303757 | F22: 0.27936814 | G22: 0.020411163 | H22: 0.24705564 | I22: 0.31414356 | J22: =F22*(F22*(1-F22)/G22^2-1) -> 134.72 | K22: =(1-F22)*(F22*(1-F22)/G22^2-1) -> 347.51107 | L22: =J22/(J22+K22) -> 0.27936814
A23: E2 | B23: 2023 | C23: observado y ajustado | D23: 175 | E23: 0.27695135 | F23: 0.28704363 | G23: 0.023805485 | H23: 0.2495268 | I23: 0.32773783 | J23: =F23*(F23*(1-F23)/G23^2-1) -> 103.3714 | K23: =(1-F23)*(F23*(1-F23)/G23^2-1) -> 256.75296 | L23: =J23/(J23+K23) -> 0.28704363
A24: E2 | B24: 2024 | C24: observado y ajustado | D24: 161 | E24: 0.34181559 | F24: 0.29484371 | G24: 0.02981641 | H24: 0.24826582 | I24: 0.34613652 | J24: =F24*(F24*(1-F24)/G24^2-1) -> 68.658988 | K24: =(1-F24)*(F24*(1-F24)/G24^2-1) -> 164.20672 | L24: =J24/(J24+K24) -> 0.29484371
A25: E2 | B25: 2025 | C25: observado y ajustado | D25: 142 | E25: 0.34612299 | F25: 0.30276574 | G25: 0.037397703 | H25: 0.24497659 | I25: 0.36755088 | J25: =F25*(F25*(1-F25)/G25^2-1) -> 45.395776 | K25: =(1-F25)*(F25*(1-F25)/G25^2-1) -> 104.54119 | L25: =J25/(J25+K25) -> 0.30276574
A26: E2 | B26: 2026 | C26: extrapolado | F26: 0.31080681 | G26: 0.045935303 | H26: 0.24065142 | I26: 0.39088617 | J26: =F26*(F26*(1-F26)/G26^2-1) -> 31.241336 | K26: =(1-F26)*(F26*(1-F26)/G26^2-1) -> 69.275561 | L26: =J26/(J26+K26) -> 0.31080681
A27: E2 | B27: 2027 | C27: extrapolado | F27: 0.31896374 | G27: 0.055113518 | H27: 0.23579024 | I27: 0.41552371 | J27: =F27*(F27*(1-F27)/G27^2-1) -> 22.491631 | K27: =(1-F27)*(F27*(1-F27)/G27^2-1) -> 48.023063 | L27: =J27/(J27+K27) -> 0.31896374
A28: E3 | B28: 2015 | C28: extrapolado | F28: 0.32698279 | G28: 0.041475361 | H28: 0.26271702 | I28: 0.39847282 | J28: =F28*(F28*(1-F28)/G28^2-1) -> 41.503762 | K28: =(1-F28)*(F28*(1-F28)/G28^2-1) -> 85.425739 | L28: =J28/(J28+K28) -> 0.32698279
A29: E3 | B29: 2016 | C29: extrapolado | F29: 0.3433439 | G29: 0.036829798 | H29: 0.28553965 | I29: 0.40619704 | J29: =F29*(F29*(1-F29)/G29^2-1) -> 56.725356 | K29: =(1-F29)*(F29*(1-F29)/G29^2-1) -> 108.48905 | L29: =J29/(J29+K29) -> 0.3433439
A30: E3 | B30: 2017 | C30: extrapolado | F30: 0.36008565 | G30: 0.032021443 | H30: 0.30925726 | I30: 0.41425789 | J30: =F30*(F30*(1-F30)/G30^2-1) -> 80.559135 | K30: =(1-F30)*(F30*(1-F30)/G30^2-1) -> 143.16301 | L30: =J30/(J30+K30) -> 0.36008565
A31: E3 | B31: 2018 | C31: observado y ajustado | D31: 166 | E31: 0.34040965 | F31: 0.37717485 | G31: 0.027195198 | H31: 0.33358986 | I31: 0.42284117 | J31: =F31*(F31*(1-F31)/G31^2-1) -> 119.42567 | K31: =(1-F31)*(F31*(1-F31)/G31^2-1) -> 197.20645 | L31: =J31/(J31+K31) -> 0.37717485
A32: E3 | B32: 2019 | C32: observado y ajustado | D32: 148 | E32: 0.41736461 | F32: 0.394575 | G32: 0.022605496 | H32: 0.35806187 | I32: 0.43230405 | J32: =F32*(F32*(1-F32)/G32^2-1) -> 184.06083 | K32: =(1-F32)*(F32*(1-F32)/G32^2-1) -> 282.41786 | L32: =J32/(J32+K32) -> 0.394575
A33: E3 | B33: 2020 | C33: observado, no usado en el ajuste | D33: 145 | E33: 0.50589666 | F33: 0.41224654 | G33: 0.018721698 | H33: 0.38182955 | I33: 0.44334878 | J33: =F33*(F33*(1-F33)/G33^2-1) -> 284.57063 | K33: =(1-F33)*(F33*(1-F33)/G33^2-1) -> 405.72171 | L33: =J33/(J33+K33) -> 0.41224654
A34: E3 | B34: 2021 | C34: observado y ajustado | D34: 143 | E34: 0.49290127 | F34: 0.43014722 | G34: 0.016348763 | H34: 0.40348459 | I34: 0.45722128 | J34: =F34*(F34*(1-F34)/G34^2-1) -> 394.0518 | K34: =(1-F34)*(F34*(1-F34)/G34^2-1) -> 522.03409 | L34: =J34/(J34+K34) -> 0.43014722
A35: E3 | B35: 2022 | C35: observado y ajustado | D35: 131 | E35: 0.42868499 | F35: 0.44823241 | G35: 0.016385878 | H35: 0.42145522 | I35: 0.47531317 | J35: =F35*(F35*(1-F35)/G35^2-1) -> 412.43122 | K35: =(1-F35)*(F35*(1-F35)/G35^2-1) -> 507.69685 | L35: =J35/(J35+K35) -> 0.44823241
A36: E3 | B36: 2023 | C36: observado y ajustado | D36: 127 | E36: 0.45703668 | F36: 0.46645557 | G36: 0.018943003 | H36: 0.43546497 | I36: 0.49770725 | J36: =F36*(F36*(1-F36)/G36^2-1) -> 323.04787 | K36: =(1-F36)*(F36*(1-F36)/G36^2-1) -> 369.51084 | L36: =J36/(J36+K36) -> 0.46645557
A37: E3 | B37: 2024 | C37: observado y ajustado | D37: 125 | E37: 0.45807428 | F37: 0.48476869 | G37: 0.023243318 | H37: 0.44669652 | I37: 0.52301846 | J37: =F37*(F37*(1-F37)/G37^2-1) -> 223.6324 | K37: =(1-F37)*(F37*(1-F37)/G37^2-1) -> 237.68535 | L37: =J37/(J37+K37) -> 0.48476869
A38: E3 | B38: 2025 | C38: observado y ajustado | D38: 126 | E38: 0.50986917 | F38: 0.5031228 | G38: 0.028491807 | H38: 0.45636329 | I38: 0.54982775 | J38: =F38*(F38*(1-F38)/G38^2-1) -> 154.43456 | K38: =(1-F38)*(F38*(1-F38)/G38^2-1) -> 152.51746 | L38: =J38/(J38+K38) -> 0.5031228
A39: E3 | B39: 2026 | C39: extrapolado | F39: 0.5214685 | G39: 0.034198492 | H39: 0.46517775 | I39: 0.57721927 | J39: =F39*(F39*(1-F39)/G39^2-1) -> 110.74205 | K39: =(1-F39)*(F39*(1-F39)/G39^2-1) -> 101.6237 | L39: =J39/(J39+K39) -> 0.5214685
A40: E3 | B40: 2027 | C40: extrapolado | F40: 0.53975648 | G40: 0.040084764 | H40: 0.47350644 | I40: 0.60463085 | J40: =F40*(F40*(1-F40)/G40^2-1) -> 82.909936 | K40: =(1-F40)*(F40*(1-F40)/G40^2-1) -> 70.696255 | L40: =J40/(J40+K40) -> 0.53975648
...

Sheet Ciudad_postestratificada
A1: Año | B1: Peso SUI E1 | C1: Peso SUI E2 | D1: Peso SUI E3 | E1: Peso SUI E4 | F1: Peso SUI E5 | G1: Peso SUI E6 | H1: p suavizada E1 | I1: p suavizada E2 | J1: p suavizada E3 | K1: p suavizada E4 | L1: p suavizada E5 | M1: p suavizada E6 | N1: % AC ciudad (suavizada) | O1: DE (pp) | P1: % AC ciudad (sin suavizar)
A2: 2015 | B2: 0.3382981 | C2: 0.20799872 | D2: 0.23658839 | E2: 0.13044481 | F2: 0.046644438 | G2: 0.040025539 | H2: 0.050065049 | I2: 0.22929756 | J2: 0.32698279 | K2: 0.6237954 | L2: 0.79772269 | M2: 0.93704985 | N2: =SUMPRODUCT(B2:G2,H2:M2) -> 0.29807697 | O2: =SQRT((B2*0.019119)^2+(C2*0.054021)^2+(D2*0.041475)^2+(E2*0.157913)^2+(F2*0.127079)^2+(G2*0.065615)^2)*100 -> 2.703188
A3: 2016 | B3: 0.33769956 | C3: 0.20362807 | D3: 0.2375736 | E3: 0.13158013 | F3: 0.048071285 | G3: 0.041447343 | H3: 0.055992381 | I3: 0.23604799 | J3: 0.3433439 | K3: 0.64483165 | L3: 0.80912155 | M3: 0.94727923 | N3: =SUMPRODUCT(B3:G3,H3:M3) -> 0.3115488 | O3: =SQRT((B3*0.018546)^2+(C3*0.047784)^2+(D3*0.03683)^2+(E3*0.13148)^2+(F3*0.105193)^2+(G3*0.045287)^2)*100 -> 2.3213144
A4: 2017 | B4: 0.3400636 | C4: 0.20047448 | D4: 0.23295139 | E4: 0.1336362 | F4: 0.049925126 | G4: 0.042949203 | H4: 0.062575239 | I4: 0.24293451 | J4: 0.36008565 | K4: 0.66532272 | L4: 0.82002299 | M4: 0.95592452 | N4: =SUMPRODUCT(B4:G4,H4:M4) -> 0.32477133 | O4: =SQRT((B4*0.017656)^2+(C4*0.04144)^2+(D4*0.032021)^2+(E4*0.106732)^2+(F4*0.085269)^2+(G4*0.030133)^2)*100 -> 1.9594566
A5: 2018 | B5: 0.34260586 | C5: 0.20384046 | D5: 0.22927729 | E5: 0.13466891 | F5: 0.048436383 | G5: 0.041171092 | H5: 0.069874739 | I5: 0.2499562 | J5: 0.37717485 | K5: 0.6852087 | L5: 0.8304323 | M5: 0.96320719 | N5: =SUMPRODUCT(B5:G5,H5:M5) -> 0.33352405 | O5: =SQRT((B5*0.016451)^2+(C5*0.035126)^2+(D5*0.027195)^2+(E5*0.084461)^2+(F5*0.06752)^2+(G5*0.01957)^2)*100 -> 1.6205877 | P5: 0.34812589
A6: 2019 | B6: 0.33837301 | C6: 0.19930557 | D6: 0.22845093 | E6: 0.14018203 | F6: 0.05193191 | G6: 0.041756549 | H6: 0.077954927 | I6: 0.25711192 | J6: 0.394575 | K6: 0.704438 | L6: 0.84035678 | M6: 0.96932515 | N6: =SUMPRODUCT(B6:G6,H6:M6) -> 0.35062926 | O6: =SQRT((B6*0.015)^2+(C6*0.029107)^2+(D6*0.022605)^2+(E6*0.065937)^2+(F6*0.052345)^2+(G6*0.013385)^2)*100 -> 1.3387385 | P6: 0.33260328
A7: 2020 | B7: 0.33202913 | C7: 0.19894427 | D7: 0.23318128 | E7: 0.14342271 | F7: 0.052755526 | G7: 0.039667087 | H7: 0.086882214 | I7: 0.26440028 | J7: 0.41224654 | K7: 0.72296757 | L7: 0.84980545 | M7: 0.97445279 | N7: =SUMPRODUCT(B7:G7,H7:M7) -> 0.36475213 | O7: =SQRT((B7*0.013514)^2+(C7*0.023919)^2+(D7*0.018722)^2+(E7*0.053237)^2+(F7*0.040518)^2+(G7*0.01126)^2)*100 -> 1.1176038 | P7: 0.41309632
A8: 2021 | B8: 0.33745776 | C8: 0.19879969 | D8: 0.22886349 | E8: 0.13493655 | F8: 0.053615649 | G8: 0.04632686 | H8: 0.096724596 | I8: 0.27181965 | J8: 0.43014722 | K8: 0.74076297 | L8: 0.85878887 | M8: 0.97874209 | N8: =SUMPRODUCT(B8:G8,H8:M8) -> 0.37646569 | O8: =SQRT((B8*0.012501)^2+(C8*0.02058)^2+(D8*0.016349)^2+(E8*0.048734)^2+(F8*0.033327)^2+(G8*0.011598)^2)*100 -> 0.97601467 | P8: 0.39587563
A9: 2022 | B9: 0.3277154 | C9: 0.19929671 | D9: 0.23159455 | E9: 0.14550271 | F9: 0.054617131 | G9: 0.041273496 | H9: 0.10755064 | I9: 0.27936814 | J9: 0.44823241 | K9: 0.75779822 | L9: 0.86731886 | M9: 0.98232429 | N9: =SUMPRODUCT(B9:G9,H9:M9) -> 0.39290746 | O9: =SQRT((B9*0.012851)^2+(C9*0.020411)^2+(D9*0.016386)^2+(E9*0.052413)^2+(F9*0.031825)^2+(G9*0.012535)^2)*100 -> 1.0494455 | P9: 0.36646071
A10: 2023 | B10: 0.33358509 | C10: 0.19507265 | D10: 0.22898065 | E10: 0.14775313 | F10: 0.053945791 | G10: 0.040662687 | H10: 0.11942819 | I10: 0.28704363 | J10: 0.46645557 | K10: 0.77405548 | L10: 0.87540834 | M10: 0.98531191 | N10: =SUMPRODUCT(B10:G10,H10:M10) -> 0.40430227 | O10: =SQRT((B10*0.015373)^2+(C10*0.023805)^2+(D10*0.018943)^2+(E10*0.061109)^2+(F10*0.035116)^2+(G10*0.013231)^2)*100 -> 1.2332023 | P10: 0.40079861
A11: 2024 | B11: 0.33317984 | C11: 0.19300457 | D11: 0.22933587 | E11: 0.15006316 | F11: 0.05368054 | G11: 0.040736017 | H11: 0.13242282 | I11: 0.29484371 | J11: 0.48476869 | K11: 0.7895246 | L11: 0.8830711 | M11: 0.98780082 | N11: =SUMPRODUCT(B11:G11,H11:M11) -> 0.41832301 | O11: =SQRT((B11*0.020165)^2+(C11*0.029816)^2+(D11*0.023243)^2+(E11*0.071671)^2+(F11*0.04092)^2+(G11*0.013498)^2)*100 -> 1.5082105 | P11: 0.41408348
A12: 2025 | B12: 0.32176894 | C12: 0.18965601 | D12: 0.23334 | E12: 0.15694227 | F12: 0.056557904 | G12: 0.041734871 | H12: 0.14659598 | I12: 0.30276574 | J12: 0.5031228 | K12: 0.80420252 | L12: 0.89032163 | M12: 0.98987231 | N12: =SUMPRODUCT(B12:G12,H12:M12) -> 0.43987034 | O12: =SQRT((B12*0.026901)^2+(C12*0.037398)^2+(D12*0.028492)^2+(E12*0.082324)^2+(F12*0.047503)^2+(G12*0.013367)^2)*100 -> 1.8544296 | P12: 0.44873336
A13: 2026 | B13: 0.32176894 | C13: 0.18965601 | D13: 0.23334 | E13: 0.15694227 | F13: 0.056557904 | G13: 0.041734871 | H13: 0.16200283 | I13: 0.31080681 | J13: 0.5214685 | K13: 0.81809269 | L13: 0.89717492 | M13: 0.99159505 | N13: =SUMPRODUCT(B13:G13,H13:M13) -> 0.45327307 | O13: =SQRT((B13*0.035312)^2+(C13*0.045935)^2+(D13*0.034198)^2+(E13*0.092226)^2+(F13*0.053987)^2+(G13*0.012926)^2)*100 -> 2.2085976
A14: 2027 | B14: 0.32176894 | C14: 0.18965601 | D14: 0.23334 | E14: 0.15694227 | F14: 0.056557904 | G14: 0.041734871 | H14: 0.17868985 | I14: 0.31896374 | J14: 0.53975648 | K14: 0.8312043 | L14: 0.90364632 | M14: 0.99302681 | N14: =SUMPRODUCT(B14:G14,H14:M14) -> 0.46694029 | O14: =SQRT((B14*0.045251)^2+(C14*0.055114)^2+(D14*0.040085)^2+(E14*0.100997)^2+(F14*0.059977)^2+(G14*0.012264)^2)*100 -> 2.5918399
A16: Pesos = suscriptores SUI de diciembre de cada año por estrato / total E1-E6. 2026 y 2027 usan los de diciembre de 2025.
A17: Sin suavizar = serie postestratificada de Postestratificacion_AC_2018_2025.xlsx, para comparar.

Sheet Imputacion_catastro
A1: Año | B1: Estrato | C1: p objetivo (suavizada) | D1: Intercepto a | E1: b asbesto | F1: b zinc/otro | G1: P(AC|concreto) | H1: P(AC|asbesto) | I1: P(AC|zinc/otro) | J1: Viviendas catastro | K1: Fracción en edificio 4+ | L1: Concreto en hasta 3 pisos | M1: Asbesto en hasta 3 pisos | N1: Zinc/otro en hasta 3 pisos | O1: P(AC) edificio 4+ | P1: P(AC) hasta 3 pisos | Q1: P(AC) estrato (catastro) | R1: Control: diferencia con objetivo | S1: Viviendas con AC esperadas
A2: 2015 | B2: E1 | C2: 0.050065049 | D2: -2.255523 | E2: -1.0610853 | F2: -1.9538917 | G2: =1/(1+EXP(-D2)) -> 0.094874127 | H2: =1/(1+EXP(-(D2+E2))) -> 0.035005801 | I2: =1/(1+EXP(-(D2+F2))) -> 0.014637618 | J2: 108985 | K2: 0.29525164 | L2: 0 | M2: 0.81768891 | N2: 0.18231109 | O2: =G2 -> 0.094874127 | P2: =L2*G2+M2*H2+N2*I2 -> 0.031292456 | Q2: =K2*O2+(1-K2)*P2 -> 0.050065049 | R2: =Q2-C2 -> 0 | S2: =J2*Q2 -> 5456.3393
A3: 2015 | B3: E2 | C3: 0.22929756 | D3: -0.72297037 | E3: -1.0610853 | F3: -1.9538917 | G3: =1/(1+EXP(-D3)) -> 0.32673922 | H3: =1/(1+EXP(-(D3+E3))) -> 0.14380306 | I3: =1/(1+EXP(-(D3+F3))) -> 0.064352556 | J3: 72493 | K3: 0.072903591 | L3: 0.44357285 | M3: 0.51472214 | N3: 0.041705013 | O3: =G3 -> 0.32673922 | P3: =L3*G3+M3*H3+N3*I3 -> 0.22163509 | Q3: =K3*O3+(1-K3)*P3 -> 0.22929756 | R3: =Q3-C3 -> 0 | S3: =J3*Q3 -> 16622.468
A4: 2015 | B4: E3 | C4: 0.32698279 | D4: -0.16683241 | E4: -1.0610853 | F4: -1.9538917 | G4: =1/(1+EXP(-D4)) -> 0.45838837 | H4: =1/(1+EXP(-(D4+E4))) -> 0.22654608 | I4: =1/(1+EXP(-(D4+F4))) -> 0.1070988 | J4: 72000 | K4: 0.33851389 | L4: 0.16539911 | M4: 0.79143303 | N4: 0.043167861 | O4: =G4 -> 0.45838837 | P4: =L4*G4+M4*H4+N4*I4 -> 0.25973631 | Q4: =K4*O4+(1-K4)*P4 -> 0.32698279 | R4: =Q4-C4 -> 0 | S4: =J4*Q4 -> 23542.761
A5: 2015 | B5: E4 | C5: 0.6237954 | D5: 0.6322207 | E5: -1.0610853 | F5: -1.9538917 | G5: =1/(1+EXP(-D5)) -> 0.65299283 | H5: =1/(1+EXP(-(D5+E5))) -> 0.39439749 | I5: =1/(1+EXP(-(D5+F5))) -> 0.21054041 | J5: 49190 | K5: 0.69430779 | L5: 0.63064875 | M5: 0.36935125 | N5: 0 | O5: =G5 -> 0.65299283 | P5: =L5*G5+M5*H5+N5*I5 -> 0.55748032 | Q5: =K5*O5+(1-K5)*P5 -> 0.6237954 | R5: =Q5-C5 -> 0 | S5: =J5*Q5 -> 30684.496
A6: 2015 | B6: E5 | C6: 0.79772269 | D6: 1.5314386 | E6: -1.0610853 | F6: -1.9538917 | G6: =1/(1+EXP(-D6)) -> 0.82221671 | H6: =1/(1+EXP(-(D6+E6))) -> 0.61546738 | I6: =1/(1+EXP(-(D6+F6))) -> 0.3959299 | J6: 16843 | K6: 0.7378733 | L6: 0.54803504 | M6: 0.45196496 | N6: 0 | O6: =G6 -> 0.82221671 | P6: =L6*G6+M6*H6+N6*I6 -> 0.72877326 | Q6: =K6*O6+(1-K6)*P6 -> 0.79772269 | R6: =Q6-C6 -> 0 | S6: =J6*Q6 -> 13436.043
A7: 2015 | B7: E6 | C7: 0.93704985 | D7: 2.8559126 | E7: -1.0610853 | F7: -1.9538917 | G7: =1/(1+EXP(-D7)) -> 0.94562351 | H7: =1/(1+EXP(-(D7+E7))) -> 0.8575181 | I7: =1/(1+EXP(-(D7+F7))) -> 0.71136462 | J7: 13207 | K7: 0.84197774 | L7: 0.38419206 | M7: 0.61580794 | N7: 0 | O7: =G7 -> 0.94562351 | P7: =L7*G7+M7*H7+N7*I7 -> 0.8913675 | Q7: =K7*O7+(1-K7)*P7 -> 0.93704985 | R7: =Q7-C7 -> 0 | S7: =J7*Q7 -> 12375.617
A8: 2016 | B8: E1 | C8: 0.055992381 | D8: -2.1350075 | E8: -1.0610853 | F8: -1.9538917 | G8: =1/(1+EXP(-D8)) -> 0.10574054 | H8: =1/(1+EXP(-(D8+E8))) -> 0.039313021 | I8: =1/(1+EXP(-(D8+F8))) -> 0.016481478 | J8: 108985 | K8: 0.29525164 | L8: 0 | M8: 0.81768891 | N8: 0.18231109 | O8: =G8 -> 0.10574054 | P8: =L8*G8+M8*H8+N8*I8 -> 0.035150577 | Q8: =K8*O8+(1-K8)*P8 -> 0.055992381 | R8: =Q8-C8 -> 0 | S8: =J8*Q8 -> 6102.3296
A9: 2016 | B9: E2 | C9: 0.23604799 | D9: -0.68307193 | E9: -1.0610853 | F9: -1.9538917 | G9: =1/(1+EXP(-D9)) -> 0.33557603 | H9: =1/(1+EXP(-(D9+E9))) -> 0.14878566 | I9: =1/(1+EXP(-(D9+F9))) -> 0.066797059 | J9: 72493 | K9: 0.072903591 | L9: 0.44357285 | M9: 0.51472214 | N9: 0.041705013 | O9: =G9 -> 0.33557603 | P9: =L9*G9+M9*H9+N9*I9 -> 0.22822146 | Q9: =K9*O9+(1-K9)*P9 -> 0.23604799 | R9: =Q9-C9 -> -4.7184479e-15 | S9: =J9*Q9 -> 17111.827
A10: 2016 | B10: E3 | C10: 0.3433439 | D10: -0.088184148 | E10: -1.0610853 | F10: -1.9538917 | G10: =1/(1+EXP(-D10)) -> 0.47796824 | H10: =1/(1+EXP(-(D10+E10))) -> 0.24062255 | I10: =1/(1+EXP(-(D10+F10))) -> 0.11485552 | J10: 72000 | K10: 0.33851389 | L10: 0.16539911 | M10: 0.79143303 | N10: 0.043167861 | O10: =G10 -> 0.47796824 | P10: =L10*G10+M10*H10+N10*I10 -> 0.27445022 | Q10: =K10*O10+(1-K10)*P10 -> 0.3433439 | R10: =Q10-C10 -> 0 | S10: =J10*Q10 -> 24720.76
A11: 2016 | B11: E4 | C11: 0.64483165 | D11: 0.72561054 | E11: -1.0610853 | F11: -1.9538917 | G11: =1/(1+EXP(-D11)) -> 0.6738413 | H11: =1/(1+EXP(-(D11+E11))) -> 0.41690913 | I11: =1/(1+EXP(-(D11+F11))) -> 0.2264824 | J11: 49190 | K11: 0.69430779 | L11: 0.63064875 | M11: 0.36935125 | N11: 0 | O11: =G11 -> 0.6738413 | P11: =L11*G11+M11*H11+N11*I11 -> 0.57894308 | Q11: =K11*O11+(1-K11)*P11 -> 0.64483165 | R11: =Q11-C11 -> 3.9968029e-15 | S11: =J11*Q11 -> 31719.269
A12: 2016 | B12: E5 | C12: 0.80912155 | D12: 1.6056597 | E12: -1.0610853 | F12: -1.9538917 | G12: =1/(1+EXP(-D12)) -> 0.83280792 | H12: =1/(1+EXP(-(D12+E12))) -> 0.63287589 | I12: =1/(1+EXP(-(D12+F12))) -> 0.41381121 | J12: 16843 | K12: 0.7378733 | L12: 0.54803504 | M12: 0.45196496 | N12: 0 | O12: =G12 -> 0.83280792 | P12: =L12*G12+M12*H12+N12*I12 -> 0.74244565 | Q12: =K12*O12+(1-K12)*P12 -> 0.80912155 | R12: =Q12-C12 -> 0 | S12: =J12*Q12 -> 13628.034
A13: 2016 | B13: E6 | C13: 0.94727923 | D13: 3.0461519 | E13: -1.0610853 | F13: -1.9538917 | G13: =1/(1+EXP(-D13)) -> 0.9546161 | H13: =1/(1+EXP(-(D13+E13))) -> 0.87922023 | I13: =1/(1+EXP(-(D13+F13))) -> 0.74880708 | J13: 13207 | K13: 0.84197774 | L13: 0.38419206 | M13: 0.61580794 | N13: 0 | O13: =G13 -> 0.9546161 | P13: =L13*G13+M13*H13+N13*I13 -> 0.90818672 | Q13: =K13*O13+(1-K13)*P13 -> 0.94727923 | R13: =Q13-C13 -> 0 | S13: =J13*Q13 -> 12510.717
... A79: 2027 | B79: E6 | C79: 0.99302681 | D79: 5.1259238 | E79: -1.0610853 | F79: -1.9538917 | G79: =1/(1+EXP(-D79)) -> 0.99409436 | H79: =1/(1+EXP(-(D79+E79))) -> 0.98312393 | I79: =1/(1+EXP(-(D79+F79))) -> 0.95976812 | J79: 13207 | K79: 0.84197774 | L79: 0.38419206 | M79: 0.61580794 | N79: 0 | O79: =G79 -> 0.99409436 | P79: =L79*G79+M79*H79+N79*I79 -> 0.98733868 | Q79: =K79*O79+(1-K79)*P79 -> 0.99302681 | R79: =Q79-C79 -> 0 | S79: =J79*Q79 -> 13114.905
A81: Intercepto a calculado en Python (método de Brent) para que la media de las viviendas del catastro del estrato sea igual a la p objetivo (columna R = control, debe ser 0). Así E1 queda forzado a la ECV.
A82: b de techo: modelo M2 (techo + estrato) de la ECV 2024. Mezcla de techos: ECV 2024 para todos los años (simplificación: solo cambia el reparto dentro del estrato, no su total).
A83: Supuesto: vivienda en edificio de 4+ pisos (uso catastral "Apartamentos") = techo de concreto. Si cambia la p objetivo hay que recalcular a (imputacion_catastro_anual.py).

Sheet Ciudad_catastro
A1: Año | B1: Viviendas | C1: Viviendas con AC esperadas | D1: % AC ciudad (catastro)
A2: 2015 | B2: =SUMIFS(Imputacion_catastro!$J$2:$J$79,Imputacion_catastro!$A$2:$A$79,A2) -> 332718 | C2: =SUMIFS(Imputacion_catastro!$S$2:$S$79,Imputacion_catastro!$A$2:$A$79,A2) -> 102117.72 | D2: =C2/B2 -> 0.30691975
A3: 2016 | B3: =SUMIFS(Imputacion_catastro!$J$2:$J$79,Imputacion_catastro!$A$2:$A$79,A3) -> 332718 | C3: =SUMIFS(Imputacion_catastro!$S$2:$S$79,Imputacion_catastro!$A$2:$A$79,A3) -> 105792.94 | D3: =C3/B3 -> 0.31796578
A4: 2017 | B4: =SUMIFS(Imputacion_catastro!$J$2:$J$79,Imputacion_catastro!$A$2:$A$79,A4) -> 332718 | C4: =SUMIFS(Imputacion_catastro!$S$2:$S$79,Imputacion_catastro!$A$2:$A$79,A4) -> 109520.75 | D4: =C4/B4 -> 0.32916989
A5: 2018 | B5: =SUMIFS(Imputacion_catastro!$J$2:$J$79,Imputacion_catastro!$A$2:$A$79,A5) -> 332718 | C5: =SUMIFS(Imputacion_catastro!$S$2:$S$79,Imputacion_catastro!$A$2:$A$79,A5) -> 113305.43 | D5: =C5/B5 -> 0.34054493
A6: 2019 | B6: =SUMIFS(Imputacion_catastro!$J$2:$J$79,Imputacion_catastro!$A$2:$A$79,A6) -> 332718 | C6: =SUMIFS(Imputacion_catastro!$S$2:$S$79,Imputacion_catastro!$A$2:$A$79,A6) -> 117151.44 | D6: =C6/B6 -> 0.35210432
A7: 2020 | B7: =SUMIFS(Imputacion_catastro!$J$2:$J$79,Imputacion_catastro!$A$2:$A$79,A7) -> 332718 | C7: =SUMIFS(Imputacion_catastro!$S$2:$S$79,Imputacion_catastro!$A$2:$A$79,A7) -> 121063.42 | D7: =C7/B7 -> 0.36386196
A8: 2021 | B8: =SUMIFS(Imputacion_catastro!$J$2:$J$79,Imputacion_catastro!$A$2:$A$79,A8) -> 332718 | C8: =SUMIFS(Imputacion_catastro!$S$2:$S$79,Imputacion_catastro!$A$2:$A$79,A8) -> 125046.11 | D8: =C8/B8 -> 0.37583212
A9: 2022 | B9: =SUMIFS(Imputacion_catastro!$J$2:$J$79,Imputacion_catastro!$A$2:$A$79,A9) -> 332718 | C9: =SUMIFS(Imputacion_catastro!$S$2:$S$79,Imputacion_catastro!$A$2:$A$79,A9) -> 129104.28 | D9: =C9/B9 -> 0.38802913
A10: 2023 | B10: =SUMIFS(Imputacion_catastro!$J$2:$J$79,Imputacion_catastro!$A$2:$A$79,A10) -> 332718 | C10: =SUMIFS(Imputacion_catastro!$S$2:$S$79,Imputacion_catastro!$A$2:$A$79,A10) -> 133242.64 | D10: =C10/B10 -> 0.40046719
A11: 2024 | B11: =SUMIFS(Imputacion_catastro!$J$2:$J$79,Imputacion_catastro!$A$2:$A$79,A11) -> 332718 | C11: =SUMIFS(Imputacion_catastro!$S$2:$S$79,Imputacion_catastro!$A$2:$A$79,A11) -> 137465.72 | D11: =C11/B11 -> 0.41315985
A12: 2025 | B12: =SUMIFS(Imputacion_catastro!$J$2:$J$79,Imputacion_catastro!$A$2:$A$79,A12) -> 332718 | C12: =SUMIFS(Imputacion_catastro!$S$2:$S$79,Imputacion_catastro!$A$2:$A$79,A12) -> 141777.65 | D12: =C12/B12 -> 0.42611958
A13: 2026 | B13: =SUMIFS(Imputacion_catastro!$J$2:$J$79,Imputacion_catastro!$A$2:$A$79,A13) -> 332718 | C13: =SUMIFS(Imputacion_catastro!$S$2:$S$79,Imputacion_catastro!$A$2:$A$79,A13) -> 146182.02 | D13: =C13/B13 -> 0.43935712
A14: 2027 | B14: =SUMIFS(Imputacion_catastro!$J$2:$J$79,Imputacion_catastro!$A$2:$A$79,A14) -> 332718 | C14: =SUMIFS(Imputacion_catastro!$S$2:$S$79,Imputacion_catastro!$A$2:$A$79,A14) -> 150681.58 | D14: =C14/B14 -> 0.45288075

Sheet Por_posicion
A1: Posición frente a la cubierta | B1: P(AC) media 2019 | C1: P(AC) media 2024
A2: Casa (suelo y cubierta propia) | B2: 0.22643464 | C2: 0.27788861
A3: Piso intermedio | B3: 0.57283513 | C3: 0.64729908
A4: Primer piso con vivienda encima | B4: 0.35287539 | C4: 0.42114405
A5: Sin dato de piso | B5: 0.64851093 | C5: 0.73018601
A6: Último piso (bajo cubierta) | B6: 0.43809257 | C6: 0.50906687
